Workbook

Sheet Cover
A1: A320neo – Aircraft Valuation Model
A3: Purpose: | B3: Investment-grade aircraft valuation using aviation-finance methodology
A4: Prepared: | B4: 2025-12-14
A16: s

Sheet Assumptions
A1: Assumptions Table | G1: Assumption Input Table | M1: You can manipulate this table for any combination and then can select that value in assumption table to see output
A2: Category | B2: Assumption | C2: Value | D2: Notes | G2: List Price | H2: Discount | I2: Model Factor | J2: Retention% | K2: LRF | L2: FH/Year
A3: Aircraft | B3: List Price (USD) | C3: 60000000 | D3: OEM list | G3: 70000000 | H3: 0.55 | I3: 0.95 | J3: 0.87 | K3: 0.08 | L3: 5000
A4: Aircraft | B4: New Aircraft Discount | C4: 0.2 | D4: Market discount | G4: 60000000 | H4: 0.45 | I4: 0.94 | J4: 0.85 | K4: 0.075 | L4: 4500
A5: Aircraft | B5: Model Factor % | C5: 0.95 | D5: Spec adj | G5: 50000000 | H5: 0.43 | I5: 0.93 | J5: 0.84 | K5: 0.07 | L5: 4000
A6: Valuation | B6: First Year Retention % | C6: 0.85 | D6: BV(1)/BV0 | G6: 45000000 | H6: 0.4 | I6: 0.92 | J6: 0.83 | K6: 0.065 | L6: 3500
A7: Valuation | B7: BV0(Base Value) | C7: =C3*(1-C4)*C5 -> 45600000 | D7: Policy Assumption | G7: 40000000 | H7: 0.3 | I7: 0.91 | J7: 0.82 | K7: 0.06 | L7: 3000
A8: Valuation | B8: Eular Constant(k) | C8: =-LN(C6) -> 0.16251893 | D8: LN(BV(1)/BV0 | G8: 30000000 | H8: 0.2 | I8: 0.9 | J8: 0.55 | K8: 0.055 | L8: 2500
A9: Valuation | B9: Depreciation Period | C9: 12
A10: Valuation | B10: Rsidual Floor % | C10: 0.45 | D10: 45% of BV0 | G10: Output Table
A11: Valuation | B11: Depriciation/Residual | C11: =MAX(C3*(1-C4)*C5*EXP(-C8*C9),C3*(1-C4)*C5*0.45)*(1-C28) -> 19904400 | D11: Max of Exponential Depreciation or 45 % of BV0 | G11: Scenario | H11: NPV | I11: IRR | J11: WACC
A12: Valuation | B12: Economic Life (yrs) | C12: 25 | D12: Horizon | G12: Base | H12: =NPV(WACC!$B$8,Cashflow!$H$5:$H$16)+Cashflow!$H$4 -> 125394.62 | I12: =IRR(Cashflow!$H$4:$H$16) -> 0.072971752 | J12: =WACC!$B$8 -> 0.072525
A13: Market Assumption | B13: Risk Free Rate | C13: 0.04 | D13: Gvt Bonds | G13: Downside | H13: =NPV(WACC!$B$8,Cashflow!$H$20:$H$31)+Cashflow!$H$19 -> -7843742.5 | I13: =IRR(Cashflow!$H$19:$H$31) -> 0.043865955 | J13: =WACC!$B$8 -> 0.072525
A14: Market Assumption | B14: Beta | C14: 1.1 | G14: Stress | H14: =NPV(WACC!$B$8,Cashflow!$H$35:$H$46)+Cashflow!$H$34 -> -11603908 | I14: =IRR(Cashflow!$H$34:$H$46) -> 0.027947066 | J14: =WACC!$B$8 -> 0.072525
A15: Market Assumption | B15: ERP | C15: 0.055 | D15: Equity Risk Premium(Market)
A16: Market Assumption | B16: CM | C16: 0.025 | D16: Credit Margin/Spread(Secured Debt) | G16: Key Output | H16: Base
A17: Assets Specific Assumptions | B17: ARP(Assets Risk Premium) | C17: 0.015 | D17: Assets/Business Risk(Aviation Cyclicality) | G17: BV at Delivery | H17: =Base_Value!$H$2 -> 45600000
A18: Assets Specific Assumptions | B18: RVP(Residual Value Premium) | C18: 0.0075 | D18: Long-dated Exit Risk | G18: MV at Delivery | H18: =Market_Value!$E$3 -> 45600000
A19: Assets Specific Assumptions | B19: LP (Liquidity Premium) | C19: 0.005 | D19: Downtime Risk | G19: Year-1 Rent | H19: ='LRF-Model'!$E$3 -> 4722365.8
A20: Lease | B20: AF(Annuity Factor) | C20: =(1-(1+$C$34)^-$C$9)/$C$34 -> 7.8368936 | D20: Market | G20: Residual @ Lease End | H20: =Cashflow!$E$16 -> 19904400
A21: Lease | B21: PV of Residual | C21: =C11/(1+C34)^C9 -> 8591322.1 | D21: Present value of residual | G21: Project NPV | H21: =DCF!$B$3 -> 7841.2191
A22: Lease | B22: Aircraft Lease/Rent | C22: =(C7-C21)/C20 -> 4722365.8 | G22: Project IRR | H22: =DCF!$C$3 -> 0.072971752
A23: Lease | B23: LRF | C23: =C24/12 -> 0.0086300544 | G23: WACC | H23: =WACC!$B$8 -> 0.072525
A24: Lease | B24: LRF (annual) | C24: =C22/C7 -> 0.10356065
A25: Lease | B25: Lease Term (yrs) | C25: 12 | D25: Base lease
A26: Ops | B26: Flight Hours / year | C26: 3000 | D26: Utilisation
A27: Maintenance | B27: Reserve per FH | C27: 5 | D27: USD
A28: Transaction | B28: Selling Costs % | C28: 0.03 | D28: Broker + transition
A29: Finance | B29: Cost of Equity | C29: =C13+C14*C15+C17+C18+C19 -> 0.128 | D29: Hybrid
A30: Finance | B30: Cost of Debt | C30: =C13+C16 -> 0.065 | D30: Pre-tax
A31: Finance | B31: Debt Ratio | C31: 0.7 | D31: Target Capital Structure
A32: Finance | B32: Equity Ratio | C32: =1-C31 -> 0.3 | D32: Target Capital Structure
A33: Finance | B33: Tax Rate | C33: 0.25 | D33: Corp tax
A34: Finance | B34: WACC | C34: =C32*C29+C31*C30*(1-C33) -> 0.072525
A36: Note:-
A37: The Value in this Asumption Table can be manipulated according to need and output will be visible in the Output table

Sheet Sensitivity Tables
A1: Cash Flow | B1: 0 Year | C1: 1 Year | D1: 2 Year | E1: 3 Year | F1: 4 Year | G1: 5 Year | H1: 6 Year | I1: 7 Year | J1: 8 Year | K1: 9 Year | L1: 10 Year | M1: 11 Year | N1: 12 Year
A2: Rent (In Flow) | B2: {=TRANSPOSE(Cashflow!C4:C16)} -> 0 | C2: 4722365.8 | D2: 4014010.9 | E2: 3411909.3 | F2: 2900122.9 | G2: 2465104.4 | H2: 2125064.6 | I2: 2125064.6 | J2: 2125064.6 | K2: 2125064.6 | L2: 2125064.6 | M2: 2125064.6 | N2: 2125064.6
A3: Cash Out Flow(CapEx) | B3: =-Assumptions!$C$7 -> -45600000 | C3: - | D3: - | E3: - | F3: - | G3: - | H3: - | I3: - | J3: - | K3: - | L3: - | M3: - | N3: -
A4: Discounted Rent | B4: - | C4: =C2/(1+Assumptions!$C$34)^SUBSTITUTE('Sensitivity Tables'!C$1," Year","") -> 4403035.6 | D4: =D2/(1+Assumptions!$C$34)^SUBSTITUTE('Sensitivity Tables'!D$1," Year","") -> 3489504 | E4: =E2/(1+Assumptions!$C$34)^SUBSTITUTE('Sensitivity Tables'!E$1," Year","") -> 2765509.8 | F4: =F2/(1+Assumptions!$C$34)^SUBSTITUTE('Sensitivity Tables'!F$1," Year","") -> 2191728.2 | G4: =G2/(1+Assumptions!$C$34)^SUBSTITUTE('Sensitivity Tables'!G$1," Year","") -> 1736993.5 | H4: =H2/(1+Assumptions!$C$34)^SUBSTITUTE('Sensitivity Tables'!H$1," Year","") -> 1396135.6 | I4: =I2/(1+Assumptions!$C$34)^SUBSTITUTE('Sensitivity Tables'!I$1," Year","") -> 1301727.8 | J4: =J2/(1+Assumptions!$C$34)^SUBSTITUTE('Sensitivity Tables'!J$1," Year","") -> 1213703.9 | ... N4: =N2/(1+Assumptions!$C$34)^SUBSTITUTE('Sensitivity Tables'!N$1," Year","") -> 917240.12
A5: Actual Residual | B5: - | C5: - | D5: - | E5: - | F5: - | G5: - | H5: - | I5: - | J5: - | K5: - | L5: - | M5: - | N5: =Assumptions!$C$11 -> 19904400
A6: Discounted Resid | B6: - | C6: - | D6: - | E6: - | F6: - | G6: - | H6: - | I6: - | J6: - | K6: - | L6: - | M6: - | N6: =N5/(1+Assumptions!$C$34)^12 -> 8591322.1
A7: Depreciation | B7: {=TRANSPOSE(Cashflow!F4:F16)} -> 0 | C7: 0 | D7: 2090000 | E7: 2090000 | F7: 2090000 | G7: 2090000 | H7: 2090000 | I7: 2090000 | J7: 2090000 | K7: 2090000 | L7: 2090000 | M7: 2090000 | N7: 2090000
A8: Discounted Depreciation | C8: =C7/(1+Assumptions!$C$34)^SUBSTITUTE('Sensitivity Tables'!C$1," Year","") -> 0 | D8: =D7/(1+Assumptions!$C$34)^SUBSTITUTE('Sensitivity Tables'!D$1," Year","") -> 1816901.7 | E8: =E7/(1+Assumptions!$C$34)^SUBSTITUTE('Sensitivity Tables'!E$1," Year","") -> 1694041.4 | F8: =F7/(1+Assumptions!$C$34)^SUBSTITUTE('Sensitivity Tables'!F$1," Year","") -> 1579488.9 | G8: =G7/(1+Assumptions!$C$34)^SUBSTITUTE('Sensitivity Tables'!G$1," Year","") -> 1472682.6 | H8: =H7/(1+Assumptions!$C$34)^SUBSTITUTE('Sensitivity Tables'!H$1," Year","") -> 1373098.7 | I8: =I7/(1+Assumptions!$C$34)^SUBSTITUTE('Sensitivity Tables'!I$1," Year","") -> 1280248.6 | J8: =J7/(1+Assumptions!$C$34)^SUBSTITUTE('Sensitivity Tables'!J$1," Year","") -> 1193677.2 | ... N8: =N7/(1+Assumptions!$C$34)^SUBSTITUTE('Sensitivity Tables'!N$1," Year","") -> 902105.22
A9: Total Cash Flow | B9: =SUM(B2:B3,B5,B8) -> -45600000 | C9: =SUM(C2:C3,C5,C8) -> 4722365.8 | D9: =SUM(D2:D3,D5,D8) -> 5830912.6 | E9: =SUM(E2:E3,E5,E8) -> 5105950.6 | F9: =SUM(F2:F3,F5,F8) -> 4479611.8 | G9: =SUM(G2:G3,G5,G8) -> 3937787.1 | H9: =SUM(H2:H3,H5,H8) -> 3498163.2 | I9: =SUM(I2:I3,I5,I8) -> 3405313.2 | ... N9: =SUM(N2:N3,N5,N8) -> 22931570
A12: WACC | B12: =Assumptions!C34 -> 0.072525
A13: Residual | B13: =N5/(1+B12)^12 -> 8591322.1
A14: LRF | B14: =Assumptions!$C$24 -> 0.10356065
A15: NPV | B15: =+N6+SUM(C4:N4)+SUM(C8:N8)+B3 -> 7841.2191
A16: IRR | B16: =IRR(B9:N9) -> 0.0541837
A18: WACC Sensitivity
A19: WACC | B19: AF | C19: PVR | D19: Annual Rent | E19: LRF | F19: NPV
A20: 0.061 | B20: =(1-(1+A20)^-Assumptions!$C$9)/'Sensitivity Tables'!A20 -> 8.3380714 | C20: =Assumptions!$C$11/(1+'Sensitivity Tables'!A20)^Assumptions!$C$9 -> 9780577.2 | D20: =(Assumptions!$C$7-'Sensitivity Tables'!C20)/'Sensitivity Tables'!B20 -> 4295888.2 | E20: =D20/Assumptions!$C$7 -> 0.094208075 | F20: =NPV(A20,Cashflow!$C$5:$C$16)+NPV(A20,Cashflow!$F$5:$F$16)+Cashflow!$E$16/(1+'Sensitivity Tables'!A20)^12-Assumptions!$C$7 -> 3424127
A21: 0.066 | B21: =(1-(1+A21)^-Assumptions!$C$9)/'Sensitivity Tables'!A21 -> 8.1148059 | C21: =Assumptions!$C$11/(1+'Sensitivity Tables'!A21)^Assumptions!$C$9 -> 9244057.4 | D21: =(Assumptions!$C$7-'Sensitivity Tables'!C21)/'Sensitivity Tables'!B21 -> 4480198.7 | E21: =D21/Assumptions!$C$7 -> 0.098249971 | F21: =NPV(A21,Cashflow!$C$5:$C$16)+NPV(A21,Cashflow!$F$5:$F$16)+Cashflow!$E$16/(1+'Sensitivity Tables'!A21)^12-Assumptions!$C$7 -> 1896222.3
A22: 0.0725 | B22: =(1-(1+A22)^-Assumptions!$C$9)/'Sensitivity Tables'!A22 -> 7.8379304 | C22: =Assumptions!$C$11/(1+'Sensitivity Tables'!A22)^Assumptions!$C$9 -> 8593725.6 | D22: =(Assumptions!$C$7-'Sensitivity Tables'!C22)/'Sensitivity Tables'!B22 -> 4721434.4 | E22: =D22/Assumptions!$C$7 -> 0.10354023 | F22: =NPV(A22,Cashflow!$C$5:$C$16)+NPV(A22,Cashflow!$F$5:$F$16)+Cashflow!$E$16/(1+'Sensitivity Tables'!A22)^12-Assumptions!$C$7 -> 14858.138
A23: 0.076 | B23: =(1-(1+A23)^-Assumptions!$C$9)/'Sensitivity Tables'!A23 -> 7.6947947 | C23: =Assumptions!$C$11/(1+'Sensitivity Tables'!A23)^Assumptions!$C$9 -> 8264219.3 | D23: =(Assumptions!$C$7-'Sensitivity Tables'!C23)/'Sensitivity Tables'!B23 -> 4852082.7 | E23: =D23/Assumptions!$C$7 -> 0.10640532 | F23: =NPV(A23,Cashflow!$C$5:$C$16)+NPV(A23,Cashflow!$F$5:$F$16)+Cashflow!$E$16/(1+'Sensitivity Tables'!A23)^12-Assumptions!$C$7 -> -951781.95
A24: 0.081 | B24: =(1-(1+A24)^-Assumptions!$C$9)/'Sensitivity Tables'!A24 -> 7.4971873 | C24: =Assumptions!$C$11/(1+'Sensitivity Tables'!A24)^Assumptions!$C$9 -> 7817011.7 | D24: =(Assumptions!$C$7-'Sensitivity Tables'!C24)/'Sensitivity Tables'!B24 -> 5039621.7 | E24: =D24/Assumptions!$C$7 -> 0.11051802 | F24: =NPV(A24,Cashflow!$C$5:$C$16)+NPV(A24,Cashflow!$F$5:$F$16)+Cashflow!$E$16/(1+'Sensitivity Tables'!A24)^12-Assumptions!$C$7 -> -2279449.2
A27: IRR Sensitivity with LRF and NPV
A28: LRF | B28: NPV>>
A29: =B16 -> 0.0541837 | B29: 3556000.1 | C29: 1965138.8 | D29: 0 | E29: -998145.61 | F29: -2378527.5
A30: 0.094208075 | B30: 0.0541837 | C30: 0.0541837 | D30: 0.0541837 | E30: 0.0541837 | F30: 0.0541837
A31: 0.098249971 | B31: 0.0541837 | C31: 0.0541837 | D31: 0.0541837 | E31: 0.0541837 | F31: 0.0541837
A32: 0.10356065 | B32: 0.0541837 | C32: 0.0541837 | D32: 0.0541837 | E32: 0.0541837 | F32: 0.0541837
A33: 0.10640532 | B33: 0.0541837 | C33: 0.0541837 | D33: 0.0541837 | E33: 0.0541837 | F33: 0.0541837
A34: 0.11051802 | B34: 0.0541837 | C34: 0.0541837 | D34: 0.0541837 | E34: 0.0541837 | F34: 0.0541837
A37: Residual Sensitivity with WACC and LRF
A38: WACC | B38: LRF >>
A39: =B13 -> 8591322.1 | B39: 0.094208075 | C39: 0.098249971 | D39: 0.10356065 | E39: 0.10640532 | F39: 0.11051802
A40: 0.061 | B40: 9780577.2 | C40: 9780577.2 | D40: 9780577.2 | E40: 9780577.2 | F40: 9780577.2
A41: 0.066 | B41: 9244057.4 | C41: 9244057.4 | D41: 9244057.4 | E41: 9244057.4 | F41: 9244057.4
A42: 0.07253 | B42: 8590841.5 | C42: 8590841.5 | D42: 8590841.5 | E42: 8590841.5 | F42: 8590841.5
A43: 0.076 | B43: 8264219.3 | C43: 8264219.3 | D43: 8264219.3 | E43: 8264219.3 | F43: 8264219.3
A44: 0.081 | B44: 7817011.7 | C44: 7817011.7 | D44: 7817011.7 | E44: 7817011.7 | F44: 7817011.7

Sheet Scenarios
A1: Scenario Table
A2: Scenario | B2: MAF | C2: LRF Mult | D2: WACC Adj
A3: Base | B3: 1 | C3: 1 | D3: 0
A4: Downside | B4: 0.8 | C4: 0.8 | D4: 0.02
A5: Stress | B5: 0.6 | C5: 0.7 | D5: 0.04

Sheet Base_Value
A1: Year | B1: Age | C1: Base Value Depreciation
A2: 0 | B2: 0 | C2: =MAX($H$2*EXP(-$H$3*B2),Assumptions!$C$10*$H$2) -> 45600000 | G2: BV0(Base Value at the beginning) | H2: =Assumptions!C3*(1-Assumptions!$C$4)*Assumptions!$C$5 -> 45600000
A3: 1 | B3: 1 | C3: =MAX($H$2*EXP(-$H$3*B3),Assumptions!$C$10*$H$2) -> 38760000 | G3: k(Euler's Number):- Exponential | H3: =-LN(Assumptions!C6) -> 0.16251893
A4: 2 | B4: 2 | C4: =MAX($H$2*EXP(-$H$3*B4),Assumptions!$C$10*$H$2) -> 32946000 | G4: BV1 | H4: =$H$2*Assumptions!$C$6 -> 38760000 | I4: BVt/BV0=e^-kt | J4: ln(BVt/BV0)=-kt | K4: k=-LN(BV1/BV0)/1 as t=1
A5: 3 | B5: 3 | C5: =MAX($H$2*EXP(-$H$3*B5),Assumptions!$C$10*$H$2) -> 28004100
A6: 4 | B6: 4 | C6: =MAX($H$2*EXP(-$H$3*B6),Assumptions!$C$10*$H$2) -> 23803485
A7: 5 | B7: 5 | C7: =MAX($H$2*EXP(-$H$3*B7),Assumptions!$C$10*$H$2) -> 20520000
A8: 6 | B8: 6 | C8: =MAX($H$2*EXP(-$H$3*B8),Assumptions!$C$10*$H$2) -> 20520000
A9: 7 | B9: 7 | C9: =MAX($H$2*EXP(-$H$3*B9),Assumptions!$C$10*$H$2) -> 20520000
A10: 8 | B10: 8 | C10: =MAX($H$2*EXP(-$H$3*B10),Assumptions!$C$10*$H$2) -> 20520000 | G10: =C14-C2 -> -25080000
A11: 9 | B11: 9 | C11: =MAX($H$2*EXP(-$H$3*B11),Assumptions!$C$10*$H$2) -> 20520000 | G11: =G10/12 -> -2090000
A12: 10 | B12: 10 | C12: =MAX($H$2*EXP(-$H$3*B12),Assumptions!$C$10*$H$2) -> 20520000
A13: 11 | B13: 11 | C13: =MAX($H$2*EXP(-$H$3*B13),Assumptions!$C$10*$H$2) -> 20520000
A14: 12 | B14: 12 | C14: =MAX($H$2*EXP(-$H$3*B14),Assumptions!$C$10*$H$2) -> 20520000
A15: 13 | B15: 13 | C15: =MAX($H$2*EXP(-$H$3*B15),Assumptions!$C$10*$H$2) -> 20520000
A16: 14 | B16: 14 | C16: =MAX($H$2*EXP(-$H$3*B16),Assumptions!$C$10*$H$2) -> 20520000
A17: 15 | B17: 15 | C17: =MAX($H$2*EXP(-$H$3*B17),Assumptions!$C$10*$H$2) -> 20520000
A18: 16 | B18: 16 | C18: =MAX($H$2*EXP(-$H$3*B18),Assumptions!$C$10*$H$2) -> 20520000
A19: 17 | B19: 17 | C19: =MAX($H$2*EXP(-$H$3*B19),Assumptions!$C$10*$H$2) -> 20520000
A20: 18 | B20: 18 | C20: =MAX($H$2*EXP(-$H$3*B20),Assumptions!$C$10*$H$2) -> 20520000
A21: 19 | B21: 19 | C21: =MAX($H$2*EXP(-$H$3*B21),Assumptions!$C$10*$H$2) -> 20520000
A22: 20 | B22: 20 | C22: =MAX($H$2*EXP(-$H$3*B22),Assumptions!$C$10*$H$2) -> 20520000
A23: 21 | B23: 21 | C23: =MAX($H$2*EXP(-$H$3*B23),Assumptions!$C$10*$H$2) -> 20520000
... A27: 25 | B27: 25 | C27: =MAX($H$2*EXP(-$H$3*B27),Assumptions!$C$10*$H$2) -> 20520000
A31: Note:- | B31: To calculate Depreciation, exponential methos is used when ever the value is less than 45% of original BV. In case if depreciation is more than 45% of BV0, 45% of BV0 is considered as depreciation

Sheet Market_Value
A1: Impact of Market Assumption Factor (MAF) on MV and RV in different senarios
A2: Year | B2: Scenario | C2: Base Value | D2: MAF | E2: Market Value | F2: Net Residual Value
A3: 0 | B3: =Scenarios!A3 -> Base | C3: =Base_Value!C2 -> 45600000 | D3: =Scenarios!B3 -> 1 | E3: =C3*D3 -> 45600000 | F3: =E3*(1-Assumptions!$C$28) -> 44232000
A4: 0 | B4: =Scenarios!A4 -> Downside | C4: =Base_Value!C2 -> 45600000 | D4: =Scenarios!B4 -> 0.8 | E4: =C4*D4 -> 36480000 | F4: =E4*(1-Assumptions!$C$28) -> 35385600
A5: 0 | B5: =Scenarios!A5 -> Stress | C5: =Base_Value!C2 -> 45600000 | D5: =Scenarios!B5 -> 0.6 | E5: =C5*D5 -> 27360000 | F5: =E5*(1-Assumptions!$C$28) -> 26539200
A6: =A3+1 -> 1 | B6: =Scenarios!A3 -> Base | C6: =Base_Value!C3 -> 38760000 | D6: =Scenarios!B3 -> 1 | E6: =C6*D6 -> 38760000 | F6: =E6*(1-Assumptions!$C$28) -> 37597200
A7: =A4+1 -> 1 | B7: =Scenarios!A4 -> Downside | C7: =Base_Value!C3 -> 38760000 | D7: =Scenarios!B4 -> 0.8 | E7: =C7*D7 -> 31008000 | F7: =E7*(1-Assumptions!$C$28) -> 30077760
A8: =A5+1 -> 1 | B8: =Scenarios!A5 -> Stress | C8: =Base_Value!C3 -> 38760000 | D8: =Scenarios!B5 -> 0.6 | E8: =C8*D8 -> 23256000 | F8: =E8*(1-Assumptions!$C$28) -> 22558320
A9: =A6+1 -> 2 | B9: =Scenarios!A3 -> Base | C9: =Base_Value!C4 -> 32946000 | D9: =Scenarios!B3 -> 1 | E9: =C9*D9 -> 32946000 | F9: =E9*(1-Assumptions!$C$28) -> 31957620
A10: =A7+1 -> 2 | B10: =Scenarios!A4 -> Downside | C10: =Base_Value!C4 -> 32946000 | D10: =Scenarios!B4 -> 0.8 | E10: =C10*D10 -> 26356800 | F10: =E10*(1-Assumptions!$C$28) -> 25566096
A11: =A8+1 -> 2 | B11: =Scenarios!A5 -> Stress | C11: =Base_Value!C4 -> 32946000 | D11: =Scenarios!B5 -> 0.6 | E11: =C11*D11 -> 19767600 | F11: =E11*(1-Assumptions!$C$28) -> 19174572
A12: =A9+1 -> 3 | B12: =Scenarios!A3 -> Base | C12: =Base_Value!C5 -> 28004100 | D12: =Scenarios!B3 -> 1 | E12: =C12*D12 -> 28004100 | F12: =E12*(1-Assumptions!$C$28) -> 27163977
A13: =A10+1 -> 3 | B13: =Scenarios!A4 -> Downside | C13: =Base_Value!C5 -> 28004100 | D13: =Scenarios!B4 -> 0.8 | E13: =C13*D13 -> 22403280 | F13: =E13*(1-Assumptions!$C$28) -> 21731182
A14: =A11+1 -> 3 | B14: =Scenarios!A5 -> Stress | C14: =Base_Value!C5 -> 28004100 | D14: =Scenarios!B5 -> 0.6 | E14: =C14*D14 -> 16802460 | F14: =E14*(1-Assumptions!$C$28) -> 16298386
A15: =A12+1 -> 4 | B15: =Scenarios!A3 -> Base | C15: =Base_Value!C6 -> 23803485 | D15: =Scenarios!B3 -> 1 | E15: =C15*D15 -> 23803485 | F15: =E15*(1-Assumptions!$C$28) -> 23089380
A16: =A13+1 -> 4 | B16: =Scenarios!A4 -> Downside | C16: =Base_Value!C6 -> 23803485 | D16: =Scenarios!B4 -> 0.8 | E16: =C16*D16 -> 19042788 | F16: =E16*(1-Assumptions!$C$28) -> 18471504
A17: =A14+1 -> 4 | B17: =Scenarios!A5 -> Stress | C17: =Base_Value!C6 -> 23803485 | D17: =Scenarios!B5 -> 0.6 | E17: =C17*D17 -> 14282091 | F17: =E17*(1-Assumptions!$C$28) -> 13853628
A18: =A15+1 -> 5 | B18: =Scenarios!A3 -> Base | C18: =Base_Value!C7 -> 20520000 | D18: =Scenarios!B3 -> 1 | E18: =C18*D18 -> 20520000 | F18: =E18*(1-Assumptions!$C$28) -> 19904400
A19: =A16+1 -> 5 | B19: =Scenarios!A4 -> Downside | C19: =Base_Value!C7 -> 20520000 | D19: =Scenarios!B4 -> 0.8 | E19: =C19*D19 -> 16416000 | F19: =E19*(1-Assumptions!$C$28) -> 15923520
A20: =A17+1 -> 5 | B20: =Scenarios!A5 -> Stress | C20: =Base_Value!C7 -> 20520000 | D20: =Scenarios!B5 -> 0.6 | E20: =C20*D20 -> 12312000 | F20: =E20*(1-Assumptions!$C$28) -> 11942640
A21: =A18+1 -> 6 | B21: =Scenarios!A3 -> Base | C21: =Base_Value!C8 -> 20520000 | D21: =Scenarios!B3 -> 1 | E21: =C21*D21 -> 20520000 | F21: =E21*(1-Assumptions!$C$28) -> 19904400
A22: =A19+1 -> 6 | B22: =Scenarios!A4 -> Downside | C22: =Base_Value!C8 -> 20520000 | D22: =Scenarios!B4 -> 0.8 | E22: =C22*D22 -> 16416000 | F22: =E22*(1-Assumptions!$C$28) -> 15923520
A23: =A20+1 -> 6 | B23: =Scenarios!A5 -> Stress | C23: =Base_Value!C8 -> 20520000 | D23: =Scenarios!B5 -> 0.6 | E23: =C23*D23 -> 12312000 | F23: =E23*(1-Assumptions!$C$28) -> 11942640
A24: =A21+1 -> 7 | B24: =Scenarios!A3 -> Base | C24: =Base_Value!C9 -> 20520000 | D24: =Scenarios!B3 -> 1 | E24: =C24*D24 -> 20520000 | F24: =E24*(1-Assumptions!$C$28) -> 19904400
A25: =A22+1 -> 7 | B25: =Scenarios!A4 -> Downside | C25: =Base_Value!C9 -> 20520000 | D25: =Scenarios!B4 -> 0.8 | E25: =C25*D25 -> 16416000 | F25: =E25*(1-Assumptions!$C$28) -> 15923520
A26: =A23+1 -> 7 | B26: =Scenarios!A5 -> Stress | C26: =Base_Value!C9 -> 20520000 | D26: =Scenarios!B5 -> 0.6 | E26: =C26*D26 -> 12312000 | F26: =E26*(1-Assumptions!$C$28) -> 11942640
A27: =A24+1 -> 8 | B27: =Scenarios!A3 -> Base | C27: =Base_Value!C10 -> 20520000 | D27: =Scenarios!B3 -> 1 | E27: =C27*D27 -> 20520000 | F27: =E27*(1-Assumptions!$C$28) -> 19904400
A28: =A25+1 -> 8 | B28: =Scenarios!A4 -> Downside | C28: =Base_Value!C10 -> 20520000 | D28: =Scenarios!B4 -> 0.8 | E28: =C28*D28 -> 16416000 | F28: =E28*(1-Assumptions!$C$28) -> 15923520
A29: =A26+1 -> 8 | B29: =Scenarios!A5 -> Stress | C29: =Base_Value!C10 -> 20520000 | D29: =Scenarios!B5 -> 0.6 | E29: =C29*D29 -> 12312000 | F29: =E29*(1-Assumptions!$C$28) -> 11942640
A30: =A27+1 -> 9 | B30: =Scenarios!A3 -> Base | C30: =Base_Value!C11 -> 20520000 | D30: =Scenarios!B3 -> 1 | E30: =C30*D30 -> 20520000 | F30: =E30*(1-Assumptions!$C$28) -> 19904400
A31: =A28+1 -> 9 | B31: =Scenarios!A4 -> Downside | C31: =Base_Value!C11 -> 20520000 | D31: =Scenarios!B4 -> 0.8 | E31: =C31*D31 -> 16416000 | F31: =E31*(1-Assumptions!$C$28) -> 15923520
A32: =A29+1 -> 9 | B32: =Scenarios!A5 -> Stress | C32: =Base_Value!C11 -> 20520000 | D32: =Scenarios!B5 -> 0.6 | E32: =C32*D32 -> 12312000 | F32: =E32*(1-Assumptions!$C$28) -> 11942640
A33: =A30+1 -> 10 | B33: =Scenarios!A3 -> Base | C33: =Base_Value!C12 -> 20520000 | D33: =Scenarios!B3 -> 1 | E33: =C33*D33 -> 20520000 | F33: =E33*(1-Assumptions!$C$28) -> 19904400
A34: =A31+1 -> 10 | B34: =Scenarios!A4 -> Downside | C34: =Base_Value!C12 -> 20520000 | D34: =Scenarios!B4 -> 0.8 | E34: =C34*D34 -> 16416000 | F34: =E34*(1-Assumptions!$C$28) -> 15923520
A35: =A32+1 -> 10 | B35: =Scenarios!A5 -> Stress | C35: =Base_Value!C12 -> 20520000 | D35: =Scenarios!B5 -> 0.6 | E35: =C35*D35 -> 12312000 | F35: =E35*(1-Assumptions!$C$28) -> 11942640
A36: =A33+1 -> 11 | B36: =Scenarios!A3 -> Base | C36: =Base_Value!C13 -> 20520000 | D36: =Scenarios!B3 -> 1 | E36: =C36*D36 -> 20520000 | F36: =E36*(1-Assumptions!$C$28) -> 19904400
A37: =A34+1 -> 11 | B37: =Scenarios!A4 -> Downside | C37: =Base_Value!C13 -> 20520000 | D37: =Scenarios!B4 -> 0.8 | E37: =C37*D37 -> 16416000 | F37: =E37*(1-Assumptions!$C$28) -> 15923520
A38: =A35+1 -> 11 | B38: =Scenarios!A5 -> Stress | C38: =Base_Value!C13 -> 20520000 | D38: =Scenarios!B5 -> 0.6 | E38: =C38*D38 -> 12312000 | F38: =E38*(1-Assumptions!$C$28) -> 11942640
A39: =A36+1 -> 12 | B39: =Scenarios!A3 -> Base | C39: =Base_Value!C14 -> 20520000 | D39: =Scenarios!B3 -> 1 | E39: =C39*D39 -> 20520000 | F39: =E39*(1-Assumptions!$C$28) -> 19904400
A40: =A37+1 -> 12 | B40: =Scenarios!A4 -> Downside | C40: =Base_Value!C14 -> 20520000 | D40: =Scenarios!B4 -> 0.8 | E40: =C40*D40 -> 16416000 | F40: =E40*(1-Assumptions!$C$28) -> 15923520
...

Sheet LRF-Model
A1: Impact of LRF on Lease in different senarios
A2: Year | B2: Scenario | C2: Market Value | D2: LRF Used | E2: Lease Rent
A3: 0 | B3: =Scenarios!A3 -> Base | C3: =Market_Value!E3 -> 45600000 | D3: =Assumptions!C24*Scenarios!C3 -> 0.10356065 | E3: =VLOOKUP(A3,Base_Value!A:C,3,0)*D3 -> 4722365.8
A4: 0 | B4: =Scenarios!A4 -> Downside | C4: =Market_Value!E4 -> 36480000 | D4: =Assumptions!C24*Scenarios!C4 -> 0.082848522 | E4: =VLOOKUP(A4,Base_Value!A:C,3,0)*D4 -> 3777892.6
A5: 0 | B5: =Scenarios!A5 -> Stress | C5: =Market_Value!E5 -> 27360000 | D5: =Assumptions!C24*Scenarios!C5 -> 0.072492457 | E5: =VLOOKUP(A5,Base_Value!A:C,3,0)*D5 -> 3305656
A6: 1 | B6: =Scenarios!A3 -> Base | C6: =Market_Value!E6 -> 38760000 | D6: =Assumptions!C24*Scenarios!C3 -> 0.10356065 | E6: =VLOOKUP(A6,Base_Value!A:C,3,0)*D6 -> 4014010.9
A7: 1 | B7: =Scenarios!A4 -> Downside | C7: =Market_Value!E7 -> 31008000 | D7: =Assumptions!C24*Scenarios!C4 -> 0.082848522 | E7: =VLOOKUP(A7,Base_Value!A:C,3,0)*D7 -> 3211208.7
A8: 1 | B8: =Scenarios!A5 -> Stress | C8: =Market_Value!E8 -> 23256000 | D8: =Assumptions!C24*Scenarios!C5 -> 0.072492457 | E8: =VLOOKUP(A8,Base_Value!A:C,3,0)*D8 -> 2809807.6
A9: 2 | B9: =Scenarios!A3 -> Base | C9: =Market_Value!E9 -> 32946000 | D9: =Assumptions!C24*Scenarios!C3 -> 0.10356065 | E9: =VLOOKUP(A9,Base_Value!A:C,3,0)*D9 -> 3411909.3
A10: 2 | B10: =Scenarios!A4 -> Downside | C10: =Market_Value!E10 -> 26356800 | D10: =Assumptions!C24*Scenarios!C4 -> 0.082848522 | E10: =VLOOKUP(A10,Base_Value!A:C,3,0)*D10 -> 2729527.4
A11: 2 | B11: =Scenarios!A5 -> Stress | C11: =Market_Value!E11 -> 19767600 | D11: =Assumptions!C24*Scenarios!C5 -> 0.072492457 | E11: =VLOOKUP(A11,Base_Value!A:C,3,0)*D11 -> 2388336.5
A12: 3 | B12: =Scenarios!A3 -> Base | C12: =Market_Value!E12 -> 28004100 | D12: =Assumptions!C24*Scenarios!C3 -> 0.10356065 | E12: =VLOOKUP(A12,Base_Value!A:C,3,0)*D12 -> 2900122.9
A13: 3 | B13: =Scenarios!A4 -> Downside | C13: =Market_Value!E13 -> 22403280 | D13: =Assumptions!C24*Scenarios!C4 -> 0.082848522 | E13: =VLOOKUP(A13,Base_Value!A:C,3,0)*D13 -> 2320098.3
A14: 3 | B14: =Scenarios!A5 -> Stress | C14: =Market_Value!E14 -> 16802460 | D14: =Assumptions!C24*Scenarios!C5 -> 0.072492457 | E14: =VLOOKUP(A14,Base_Value!A:C,3,0)*D14 -> 2030086
A15: 4 | B15: =Scenarios!A3 -> Base | C15: =Market_Value!E15 -> 23803485 | D15: =Assumptions!C24*Scenarios!C3 -> 0.10356065 | E15: =VLOOKUP(A15,Base_Value!A:C,3,0)*D15 -> 2465104.4
A16: 4 | B16: =Scenarios!A4 -> Downside | C16: =Market_Value!E16 -> 19042788 | D16: =Assumptions!C24*Scenarios!C4 -> 0.082848522 | E16: =VLOOKUP(A16,Base_Value!A:C,3,0)*D16 -> 1972083.6
A17: 4 | B17: =Scenarios!A5 -> Stress | C17: =Market_Value!E17 -> 14282091 | D17: =Assumptions!C24*Scenarios!C5 -> 0.072492457 | E17: =VLOOKUP(A17,Base_Value!A:C,3,0)*D17 -> 1725573.1
A18: 5 | B18: =Scenarios!A3 -> Base | C18: =Market_Value!E18 -> 20520000 | D18: =Assumptions!C24*Scenarios!C3 -> 0.10356065 | E18: =VLOOKUP(A18,Base_Value!A:C,3,0)*D18 -> 2125064.6
A19: 5 | B19: =Scenarios!A4 -> Downside | C19: =Market_Value!E19 -> 16416000 | D19: =Assumptions!C24*Scenarios!C4 -> 0.082848522 | E19: =VLOOKUP(A19,Base_Value!A:C,3,0)*D19 -> 1700051.7
A20: 5 | B20: =Scenarios!A5 -> Stress | C20: =Market_Value!E20 -> 12312000 | D20: =Assumptions!C24*Scenarios!C5 -> 0.072492457 | E20: =VLOOKUP(A20,Base_Value!A:C,3,0)*D20 -> 1487545.2
A21: 6 | B21: =Scenarios!A3 -> Base | C21: =Market_Value!E21 -> 20520000 | D21: =Assumptions!C24*Scenarios!C3 -> 0.10356065 | E21: =VLOOKUP(A21,Base_Value!A:C,3,0)*D21 -> 2125064.6
A22: 6 | B22: =Scenarios!A4 -> Downside | C22: =Market_Value!E22 -> 16416000 | D22: =Assumptions!C24*Scenarios!C4 -> 0.082848522 | E22: =VLOOKUP(A22,Base_Value!A:C,3,0)*D22 -> 1700051.7
A23: 6 | B23: =Scenarios!A5 -> Stress | C23: =Market_Value!E23 -> 12312000 | D23: =Assumptions!C24*Scenarios!C5 -> 0.072492457 | E23: =VLOOKUP(A23,Base_Value!A:C,3,0)*D23 -> 1487545.2
A24: 7 | B24: =Scenarios!A3 -> Base | C24: =Market_Value!E24 -> 20520000 | D24: =Assumptions!C24*Scenarios!C3 -> 0.10356065 | E24: =VLOOKUP(A24,Base_Value!A:C,3,0)*D24 -> 2125064.6
A25: 7 | B25: =Scenarios!A4 -> Downside | C25: =Market_Value!E25 -> 16416000 | D25: =Assumptions!C24*Scenarios!C4 -> 0.082848522 | E25: =VLOOKUP(A25,Base_Value!A:C,3,0)*D25 -> 1700051.7
A26: 7 | B26: =Scenarios!A5 -> Stress | C26: =Market_Value!E26 -> 12312000 | D26: =Assumptions!C24*Scenarios!C5 -> 0.072492457 | E26: =VLOOKUP(A26,Base_Value!A:C,3,0)*D26 -> 1487545.2
A27: 8 | B27: =Scenarios!A3 -> Base | C27: =Market_Value!E27 -> 20520000 | D27: =Assumptions!C24*Scenarios!C3 -> 0.10356065 | E27: =VLOOKUP(A27,Base_Value!A:C,3,0)*D27 -> 2125064.6
A28: 8 | B28: =Scenarios!A4 -> Downside | C28: =Market_Value!E28 -> 16416000 | D28: =Assumptions!C24*Scenarios!C4 -> 0.082848522 | E28: =VLOOKUP(A28,Base_Value!A:C,3,0)*D28 -> 1700051.7
A29: 8 | B29: =Scenarios!A5 -> Stress | C29: =Market_Value!E29 -> 12312000 | D29: =Assumptions!C24*Scenarios!C5 -> 0.072492457 | E29: =VLOOKUP(A29,Base_Value!A:C,3,0)*D29 -> 1487545.2
A30: 9 | B30: =Scenarios!A3 -> Base | C30: =Market_Value!E30 -> 20520000 | D30: =Assumptions!C24*Scenarios!C3 -> 0.10356065 | E30: =VLOOKUP(A30,Base_Value!A:C,3,0)*D30 -> 2125064.6
A31: 9 | B31: =Scenarios!A4 -> Downside | C31: =Market_Value!E31 -> 16416000 | D31: =Assumptions!C24*Scenarios!C4 -> 0.082848522 | E31: =VLOOKUP(A31,Base_Value!A:C,3,0)*D31 -> 1700051.7
A32: 9 | B32: =Scenarios!A5 -> Stress | C32: =Market_Value!E32 -> 12312000 | D32: =Assumptions!C24*Scenarios!C5 -> 0.072492457 | E32: =VLOOKUP(A32,Base_Value!A:C,3,0)*D32 -> 1487545.2
A33: 10 | B33: =Scenarios!A3 -> Base | C33: =Market_Value!E33 -> 20520000 | D33: =Assumptions!C24*Scenarios!C3 -> 0.10356065 | E33: =VLOOKUP(A33,Base_Value!A:C,3,0)*D33 -> 2125064.6
A34: 10 | B34: =Scenarios!A4 -> Downside | C34: =Market_Value!E34 -> 16416000 | D34: =Assumptions!C24*Scenarios!C4 -> 0.082848522 | E34: =VLOOKUP(A34,Base_Value!A:C,3,0)*D34 -> 1700051.7
A35: 10 | B35: =Scenarios!A5 -> Stress | C35: =Market_Value!E35 -> 12312000 | D35: =Assumptions!C24*Scenarios!C5 -> 0.072492457 | E35: =VLOOKUP(A35,Base_Value!A:C,3,0)*D35 -> 1487545.2
A36: 11 | B36: =Scenarios!A3 -> Base | C36: =Market_Value!E36 -> 20520000 | D36: =Assumptions!C24*Scenarios!C3 -> 0.10356065 | E36: =VLOOKUP(A36,Base_Value!A:C,3,0)*D36 -> 2125064.6
A37: 11 | B37: =Scenarios!A4 -> Downside | C37: =Market_Value!E37 -> 16416000 | D37: =Assumptions!C24*Scenarios!C4 -> 0.082848522 | E37: =VLOOKUP(A37,Base_Value!A:C,3,0)*D37 -> 1700051.7
A38: 11 | B38: =Scenarios!A5 -> Stress | C38: =Market_Value!E38 -> 12312000 | D38: =Assumptions!C24*Scenarios!C5 -> 0.072492457 | E38: =VLOOKUP(A38,Base_Value!A:C,3,0)*D38 -> 1487545.2
A39: 12 | B39: =Scenarios!A3 -> Base | C39: =Market_Value!E39 -> 20520000 | D39: =Assumptions!C24*Scenarios!C3 -> 0.10356065 | E39: =VLOOKUP(A39,Base_Value!A:C,3,0)*D39 -> 2125064.6
A40: 12 | B40: =Scenarios!A4 -> Downside | C40: =Market_Value!E40 -> 16416000 | D40: =Assumptions!C24*Scenarios!C4 -> 0.082848522 | E40: =VLOOKUP(A40,Base_Value!A:C,3,0)*D40 -> 1700051.7
...

Sheet Cashflow
A1: Cash Flow Generated From Lease In Different Scenarios
A2: Year | B2: Scenario | C2: Lease Rent | D2: Maint Reserves | E2: Sale Proceeds | F2: Depreciation | G2: Puchase | H2: Net Cashflow
A4: 0 | B4: =Scenarios!A3 -> Base | C4: =IF(A4=0,0,VLOOKUP(A4,Base_Value!$B$1:$C$27,2,0)*Assumptions!$C$24) -> 0 | D4: =IF(A4=0,0,Assumptions!$C$26*Assumptions!$C$27) -> 0 | E4: 0 | F4: =IF(OR(A4=0,A4=1),0,(VLOOKUP($A$4,Base_Value!$B$1:$C$27,2,0)-VLOOKUP($A$16,Base_Value!$B$1:$C$27,2,0))/12) -> 0 | G4: =-Base_Value!$C$2 -> -45600000 | H4: =SUM(C4:G4) -> -45600000
A5: 1 | B5: =Scenarios!A3 -> Base | C5: =IF(A5=0,0,VLOOKUP(A5-1,Base_Value!$B$1:$C$27,2,0)*Assumptions!$C$24) -> 4722365.8 | D5: =IF(A5=0,0,Assumptions!$C$26*Assumptions!$C$27) -> 15000 | E5: 0 | F5: =IF(OR(A5=0,A5=1),0,(VLOOKUP($A$4,Base_Value!$B$1:$C$27,2,0)-VLOOKUP($A$16,Base_Value!$B$1:$C$27,2,0))/12) -> 0 | H5: =SUM(C5:G5) -> 4737365.8 | R5: Base | S5: =NPV(Assumptions!$C$34,Cashflow!$C$5:$C$16)+Cashflow!$E$16/(1+Assumptions!$C$34)^12-Assumptions!$C$7 -> -14422594 | T5: =IRR(Cashflow!$H$4:$H$16) -> 0.072971752
A6: 2 | B6: =Scenarios!A3 -> Base | C6: =IF(A6=0,0,VLOOKUP(A6-1,Base_Value!$B$1:$C$27,2,0)*Assumptions!$C$24) -> 4014010.9 | D6: =IF(A6=0,0,Assumptions!$C$26*Assumptions!$C$27) -> 15000 | E6: 0 | F6: =IF(OR(A6=0,A6=1),0,(VLOOKUP($A$4,Base_Value!$B$1:$C$27,2,0)-VLOOKUP($A$16,Base_Value!$B$1:$C$27,2,0))/12) -> 2090000 | H6: =SUM(C6:G6) -> 6119010.9
A7: 3 | B7: =Scenarios!A3 -> Base | C7: =IF(A7=0,0,VLOOKUP(A7-1,Base_Value!$B$1:$C$27,2,0)*Assumptions!$C$24) -> 3411909.3 | D7: =IF(A7=0,0,Assumptions!$C$26*Assumptions!$C$27) -> 15000 | E7: 0 | F7: =IF(OR(A7=0,A7=1),0,(VLOOKUP($A$4,Base_Value!$B$1:$C$27,2,0)-VLOOKUP($A$16,Base_Value!$B$1:$C$27,2,0))/12) -> 2090000 | H7: =SUM(C7:G7) -> 5516909.3
A8: 4 | B8: =Scenarios!A3 -> Base | C8: =IF(A8=0,0,VLOOKUP(A8-1,Base_Value!$B$1:$C$27,2,0)*Assumptions!$C$24) -> 2900122.9 | D8: =IF(A8=0,0,Assumptions!$C$26*Assumptions!$C$27) -> 15000 | E8: 0 | F8: =IF(OR(A8=0,A8=1),0,(VLOOKUP($A$4,Base_Value!$B$1:$C$27,2,0)-VLOOKUP($A$16,Base_Value!$B$1:$C$27,2,0))/12) -> 2090000 | H8: =SUM(C8:G8) -> 5005122.9
A9: 5 | B9: =Scenarios!A3 -> Base | C9: =IF(A9=0,0,VLOOKUP(A9-1,Base_Value!$B$1:$C$27,2,0)*Assumptions!$C$24) -> 2465104.4 | D9: =IF(A9=0,0,Assumptions!$C$26*Assumptions!$C$27) -> 15000 | E9: 0 | F9: =IF(OR(A9=0,A9=1),0,(VLOOKUP($A$4,Base_Value!$B$1:$C$27,2,0)-VLOOKUP($A$16,Base_Value!$B$1:$C$27,2,0))/12) -> 2090000 | H9: =SUM(C9:G9) -> 4570104.4 | R9: Key Output | S9: Base
A10: 6 | B10: =Scenarios!A3 -> Base | C10: =IF(A10=0,0,VLOOKUP(A10-1,Base_Value!$B$1:$C$27,2,0)*Assumptions!$C$24) -> 2125064.6 | D10: =IF(A10=0,0,Assumptions!$C$26*Assumptions!$C$27) -> 15000 | E10: 0 | F10: =IF(OR(A10=0,A10=1),0,(VLOOKUP($A$4,Base_Value!$B$1:$C$27,2,0)-VLOOKUP($A$16,Base_Value!$B$1:$C$27,2,0))/12) -> 2090000 | H10: =SUM(C10:G10) -> 4230064.6 | R10: LRF | S10: =Assumptions!$C$24 -> 0.10356065
A11: 7 | B11: =Scenarios!A3 -> Base | C11: =IF(A11=0,0,VLOOKUP(A11-1,Base_Value!$B$1:$C$27,2,0)*Assumptions!$C$24) -> 2125064.6 | D11: =IF(A11=0,0,Assumptions!$C$26*Assumptions!$C$27) -> 15000 | E11: 0 | F11: =IF(OR(A11=0,A11=1),0,(VLOOKUP($A$4,Base_Value!$B$1:$C$27,2,0)-VLOOKUP($A$16,Base_Value!$B$1:$C$27,2,0))/12) -> 2090000 | H11: =SUM(C11:G11) -> 4230064.6 | R11: BV at Delivery | S11: =Base_Value!$H$2 -> 45600000
A12: 8 | B12: =Scenarios!A3 -> Base | C12: =IF(A12=0,0,VLOOKUP(A12-1,Base_Value!$B$1:$C$27,2,0)*Assumptions!$C$24) -> 2125064.6 | D12: =IF(A12=0,0,Assumptions!$C$26*Assumptions!$C$27) -> 15000 | E12: 0 | F12: =IF(OR(A12=0,A12=1),0,(VLOOKUP($A$4,Base_Value!$B$1:$C$27,2,0)-VLOOKUP($A$16,Base_Value!$B$1:$C$27,2,0))/12) -> 2090000 | H12: =SUM(C12:G12) -> 4230064.6 | R12: MV at Delivery | S12: =Market_Value!$E$3 -> 45600000
A13: 9 | B13: =Scenarios!A3 -> Base | C13: =IF(A13=0,0,VLOOKUP(A13-1,Base_Value!$B$1:$C$27,2,0)*Assumptions!$C$24) -> 2125064.6 | D13: =IF(A13=0,0,Assumptions!$C$26*Assumptions!$C$27) -> 15000 | E13: 0 | F13: =IF(OR(A13=0,A13=1),0,(VLOOKUP($A$4,Base_Value!$B$1:$C$27,2,0)-VLOOKUP($A$16,Base_Value!$B$1:$C$27,2,0))/12) -> 2090000 | H13: =SUM(C13:G13) -> 4230064.6 | R13: Year-1 Rent | S13: ='LRF-Model'!$E$3 -> 4722365.8
A14: 10 | B14: =Scenarios!A3 -> Base | C14: =IF(A14=0,0,VLOOKUP(A14-1,Base_Value!$B$1:$C$27,2,0)*Assumptions!$C$24) -> 2125064.6 | D14: =IF(A14=0,0,Assumptions!$C$26*Assumptions!$C$27) -> 15000 | E14: 0 | F14: =IF(OR(A14=0,A14=1),0,(VLOOKUP($A$4,Base_Value!$B$1:$C$27,2,0)-VLOOKUP($A$16,Base_Value!$B$1:$C$27,2,0))/12) -> 2090000 | H14: =SUM(C14:G14) -> 4230064.6 | R14: Residual @ Lease End | S14: =Cashflow!$E$16 -> 19904400
A15: 11 | B15: =Scenarios!A3 -> Base | C15: =IF(A15=0,0,VLOOKUP(A15-1,Base_Value!$B$1:$C$27,2,0)*Assumptions!$C$24) -> 2125064.6 | D15: =IF(A15=0,0,Assumptions!$C$26*Assumptions!$C$27) -> 15000 | E15: 0 | F15: =IF(OR(A15=0,A15=1),0,(VLOOKUP($A$4,Base_Value!$B$1:$C$27,2,0)-VLOOKUP($A$16,Base_Value!$B$1:$C$27,2,0))/12) -> 2090000 | H15: =SUM(C15:G15) -> 4230064.6 | R15: Project NPV | S15: =DCF!$B$3 -> 7841.2191
A16: 12 | B16: =Scenarios!A3 -> Base | C16: =IF(A16=0,0,VLOOKUP(A16-1,Base_Value!$B$1:$C$27,2,0)*Assumptions!$C$24) -> 2125064.6 | D16: =IF(A16=0,0,Assumptions!$C$26*Assumptions!$C$27) -> 15000 | E16: =Assumptions!$C$11 -> 19904400 | F16: =IF(OR(A16=0,A16=1),0,(VLOOKUP($A$4,Base_Value!$B$1:$C$27,2,0)-VLOOKUP($A$16,Base_Value!$B$1:$C$27,2,0))/12) -> 2090000 | H16: =SUM(C16:G16) -> 24134465 | R16: Project IRR | S16: =DCF!$C$3 -> 0.072971752
B17: Total Cash Generated | C17: =SUM(C4:C16) -> 32388965 | D17: =SUM(D4:D16) -> 180000 | E17: =SUM(E4:E16) -> 19904400 | F17: =SUM(F4:F16) -> 22990000 | H17: =SUM(H4:H16) -> 29863365 | R17: WACC | S17: =WACC!$B$8 -> 0.072525
A19: 0 | B19: =Scenarios!A4 -> Downside | C19: =IF(A19=0,0,VLOOKUP(A19,Base_Value!$B$1:$C$27,2,0)*Assumptions!$C$24*Scenarios!$C$4) -> 0 | D19: =IF(A19=0,0,Assumptions!$C$26*Assumptions!$C$27) -> 0 | E19: 0 | F19: =IF(OR(A19=0,A19=1),0,(VLOOKUP($A$19,Base_Value!$B$1:$C$27,2,0)-VLOOKUP($A$31,Base_Value!$B$1:$C$27,2,0))/12) -> 0 | G19: =-Base_Value!$C$2 -> -45600000 | H19: =SUM(C19:G19) -> -45600000
A20: 1 | B20: =Scenarios!A4 -> Downside | C20: =IF(A20=0,0,VLOOKUP(A20,Base_Value!$B$1:$C$27,2,0)*Assumptions!$C$24*Scenarios!$C$4) -> 3211208.7 | D20: =IF(A20=0,0,Assumptions!$C$26*Assumptions!$C$27) -> 15000 | E20: 0 | F20: =IF(OR(A20=0,A20=1),0,(VLOOKUP($A$19,Base_Value!$B$1:$C$27,2,0)-VLOOKUP($A$31,Base_Value!$B$1:$C$27,2,0))/12) -> 0 | H20: =SUM(C20:G20) -> 3226208.7
A21: 2 | B21: =Scenarios!A4 -> Downside | C21: =IF(A21=0,0,VLOOKUP(A21,Base_Value!$B$1:$C$27,2,0)*Assumptions!$C$24*Scenarios!$C$4) -> 2729527.4 | D21: =IF(A21=0,0,Assumptions!$C$26*Assumptions!$C$27) -> 15000 | E21: 0 | F21: =IF(OR(A21=0,A21=1),0,(VLOOKUP($A$19,Base_Value!$B$1:$C$27,2,0)-VLOOKUP($A$31,Base_Value!$B$1:$C$27,2,0))/12) -> 2090000 | H21: =SUM(C21:G21) -> 4834527.4
A22: 3 | B22: =Scenarios!A4 -> Downside | C22: =IF(A22=0,0,VLOOKUP(A22,Base_Value!$B$1:$C$27,2,0)*Assumptions!$C$24*Scenarios!$C$4) -> 2320098.3 | D22: =IF(A22=0,0,Assumptions!$C$26*Assumptions!$C$27) -> 15000 | E22: 0 | F22: =IF(OR(A22=0,A22=1),0,(VLOOKUP($A$19,Base_Value!$B$1:$C$27,2,0)-VLOOKUP($A$31,Base_Value!$B$1:$C$27,2,0))/12) -> 2090000 | H22: =SUM(C22:G22) -> 4425098.3
A23: 4 | B23: =Scenarios!A4 -> Downside | C23: =IF(A23=0,0,VLOOKUP(A23,Base_Value!$B$1:$C$27,2,0)*Assumptions!$C$24*Scenarios!$C$4) -> 1972083.6 | D23: =IF(A23=0,0,Assumptions!$C$26*Assumptions!$C$27) -> 15000 | E23: 0 | F23: =IF(OR(A23=0,A23=1),0,(VLOOKUP($A$19,Base_Value!$B$1:$C$27,2,0)-VLOOKUP($A$31,Base_Value!$B$1:$C$27,2,0))/12) -> 2090000 | H23: =SUM(C23:G23) -> 4077083.6
A24: 5 | B24: =Scenarios!A4 -> Downside | C24: =IF(A24=0,0,VLOOKUP(A24,Base_Value!$B$1:$C$27,2,0)*Assumptions!$C$24*Scenarios!$C$4) -> 1700051.7 | D24: =IF(A24=0,0,Assumptions!$C$26*Assumptions!$C$27) -> 15000 | E24: 0 | F24: =IF(OR(A24=0,A24=1),0,(VLOOKUP($A$19,Base_Value!$B$1:$C$27,2,0)-VLOOKUP($A$31,Base_Value!$B$1:$C$27,2,0))/12) -> 2090000 | H24: =SUM(C24:G24) -> 3805051.7
A25: 6 | B25: =Scenarios!A4 -> Downside | C25: =IF(A25=0,0,VLOOKUP(A25,Base_Value!$B$1:$C$27,2,0)*Assumptions!$C$24*Scenarios!$C$4) -> 1700051.7 | D25: =IF(A25=0,0,Assumptions!$C$26*Assumptions!$C$27) -> 15000 | E25: 0 | F25: =IF(OR(A25=0,A25=1),0,(VLOOKUP($A$19,Base_Value!$B$1:$C$27,2,0)-VLOOKUP($A$31,Base_Value!$B$1:$C$27,2,0))/12) -> 2090000 | H25: =SUM(C25:G25) -> 3805051.7
A26: 7 | B26: =Scenarios!A4 -> Downside | C26: =IF(A26=0,0,VLOOKUP(A26,Base_Value!$B$1:$C$27,2,0)*Assumptions!$C$24*Scenarios!$C$4) -> 1700051.7 | D26: =IF(A26=0,0,Assumptions!$C$26*Assumptions!$C$27) -> 15000 | E26: 0 | F26: =IF(OR(A26=0,A26=1),0,(VLOOKUP($A$19,Base_Value!$B$1:$C$27,2,0)-VLOOKUP($A$31,Base_Value!$B$1:$C$27,2,0))/12) -> 2090000 | H26: =SUM(C26:G26) -> 3805051.7
A27: 8 | B27: =Scenarios!A4 -> Downside | C27: =IF(A27=0,0,VLOOKUP(A27,Base_Value!$B$1:$C$27,2,0)*Assumptions!$C$24*Scenarios!$C$4) -> 1700051.7 | D27: =IF(A27=0,0,Assumptions!$C$26*Assumptions!$C$27) -> 15000 | E27: 0 | F27: =IF(OR(A27=0,A27=1),0,(VLOOKUP($A$19,Base_Value!$B$1:$C$27,2,0)-VLOOKUP($A$31,Base_Value!$B$1:$C$27,2,0))/12) -> 2090000 | H27: =SUM(C27:G27) -> 3805051.7
A28: 9 | B28: =Scenarios!A4 -> Downside | C28: =IF(A28=0,0,VLOOKUP(A28,Base_Value!$B$1:$C$27,2,0)*Assumptions!$C$24*Scenarios!$C$4) -> 1700051.7 | D28: =IF(A28=0,0,Assumptions!$C$26*Assumptions!$C$27) -> 15000 | E28: 0 | F28: =IF(OR(A28=0,A28=1),0,(VLOOKUP($A$19,Base_Value!$B$1:$C$27,2,0)-VLOOKUP($A$31,Base_Value!$B$1:$C$27,2,0))/12) -> 2090000 | H28: =SUM(C28:G28) -> 3805051.7
A29: 10 | B29: =Scenarios!A4 -> Downside | C29: =IF(A29=0,0,VLOOKUP(A29,Base_Value!$B$1:$C$27,2,0)*Assumptions!$C$24*Scenarios!$C$4) -> 1700051.7 | D29: =IF(A29=0,0,Assumptions!$C$26*Assumptions!$C$27) -> 15000 | E29: 0 | F29: =IF(OR(A29=0,A29=1),0,(VLOOKUP($A$19,Base_Value!$B$1:$C$27,2,0)-VLOOKUP($A$31,Base_Value!$B$1:$C$27,2,0))/12) -> 2090000 | H29: =SUM(C29:G29) -> 3805051.7
A30: 11 | B30: =Scenarios!A4 -> Downside | C30: =IF(A30=0,0,VLOOKUP(A30,Base_Value!$B$1:$C$27,2,0)*Assumptions!$C$24*Scenarios!$C$4) -> 1700051.7 | D30: =IF(A30=0,0,Assumptions!$C$26*Assumptions!$C$27) -> 15000 | E30: 0 | F30: =IF(OR(A30=0,A30=1),0,(VLOOKUP($A$19,Base_Value!$B$1:$C$27,2,0)-VLOOKUP($A$31,Base_Value!$B$1:$C$27,2,0))/12) -> 2090000 | H30: =SUM(C30:G30) -> 3805051.7
A31: 12 | B31: =Scenarios!A4 -> Downside | C31: =IF(A31=0,0,VLOOKUP(A31,Base_Value!$B$1:$C$27,2,0)*Assumptions!$C$24*Scenarios!$C$4) -> 1700051.7 | D31: =IF(A31=0,0,Assumptions!$C$26*Assumptions!$C$27) -> 15000 | E31: =Market_Value!E40*(1-Assumptions!C28) -> 15923520 | F31: =IF(OR(A31=0,A31=1),0,(VLOOKUP($A$19,Base_Value!$B$1:$C$27,2,0)-VLOOKUP($A$31,Base_Value!$B$1:$C$27,2,0))/12) -> 2090000 | H31: =SUM(C31:G31) -> 19728572
B32: Total Cash Generated | C32: =SUM(C19:C31) -> 23833331 | D32: =SUM(D19:D31) -> 180000 | E32: =SUM(E19:E31) -> 15923520 | H32: =SUM(H19:H31) -> 17326851
A34: 0 | B34: =Scenarios!A5 -> Stress | C34: =IF(A34=0,0,VLOOKUP(A34,Base_Value!$B$1:$C$27,2,0)*Assumptions!$C$24*Scenarios!$C$5) -> 0 | D34: =IF(A34=0,0,Assumptions!$C$26*Assumptions!$C$27) -> 0 | E34: 0 | F34: =IF(OR(A34=0,A34=1),0,(VLOOKUP($A$34,Base_Value!$B$1:$C$27,2,0)-VLOOKUP($A$46,Base_Value!$B$1:$C$27,2,0))/12) -> 0 | G34: =-Base_Value!$C$2 -> -45600000 | H34: =SUM(C34:G34) -> -45600000
A35: 1 | B35: =Scenarios!A5 -> Stress | C35: =IF(A35=0,0,VLOOKUP(A35,Base_Value!$B$1:$C$27,2,0)*Assumptions!$C$24*Scenarios!$C$5) -> 2809807.6 | D35: =IF(A35=0,0,Assumptions!$C$26*Assumptions!$C$27) -> 15000 | E35: 0 | F35: =IF(OR(A35=0,A35=1),0,(VLOOKUP($A$34,Base_Value!$B$1:$C$27,2,0)-VLOOKUP($A$46,Base_Value!$B$1:$C$27,2,0))/12) -> 0 | H35: =SUM(C35:G35) -> 2824807.6
A36: 2 | B36: =Scenarios!A5 -> Stress | C36: =IF(A36=0,0,VLOOKUP(A36,Base_Value!$B$1:$C$27,2,0)*Assumptions!$C$24*Scenarios!$C$5) -> 2388336.5 | D36: =IF(A36=0,0,Assumptions!$C$26*Assumptions!$C$27) -> 15000 | E36: 0 | F36: =IF(OR(A36=0,A36=1),0,(VLOOKUP($A$34,Base_Value!$B$1:$C$27,2,0)-VLOOKUP($A$46,Base_Value!$B$1:$C$27,2,0))/12) -> 2090000 | H36: =SUM(C36:G36) -> 4493336.5
A37: 3 | B37: =Scenarios!A5 -> Stress | C37: =IF(A37=0,0,VLOOKUP(A37,Base_Value!$B$1:$C$27,2,0)*Assumptions!$C$24*Scenarios!$C$5) -> 2030086 | D37: =IF(A37=0,0,Assumptions!$C$26*Assumptions!$C$27) -> 15000 | E37: 0 | F37: =IF(OR(A37=0,A37=1),0,(VLOOKUP($A$34,Base_Value!$B$1:$C$27,2,0)-VLOOKUP($A$46,Base_Value!$B$1:$C$27,2,0))/12) -> 2090000 | H37: =SUM(C37:G37) -> 4135086
A38: 4 | B38: =Scenarios!A5 -> Stress | C38: =IF(A38=0,0,VLOOKUP(A38,Base_Value!$B$1:$C$27,2,0)*Assumptions!$C$24*Scenarios!$C$5) -> 1725573.1 | D38: =IF(A38=0,0,Assumptions!$C$26*Assumptions!$C$27) -> 15000 | E38: 0 | F38: =IF(OR(A38=0,A38=1),0,(VLOOKUP($A$34,Base_Value!$B$1:$C$27,2,0)-VLOOKUP($A$46,Base_Value!$B$1:$C$27,2,0))/12) -> 2090000 | H38: =SUM(C38:G38) -> 3830573.1
A39: 5 | B39: =Scenarios!A5 -> Stress | C39: =IF(A39=0,0,VLOOKUP(A39,Base_Value!$B$1:$C$27,2,0)*Assumptions!$C$24*Scenarios!$C$5) -> 1487545.2 | D39: =IF(A39=0,0,Assumptions!$C$26*Assumptions!$C$27) -> 15000 | E39: 0 | F39: =IF(OR(A39=0,A39=1),0,(VLOOKUP($A$34,Base_Value!$B$1:$C$27,2,0)-VLOOKUP($A$46,Base_Value!$B$1:$C$27,2,0))/12) -> 2090000 | H39: =SUM(C39:G39) -> 3592545.2
A40: 6 | B40: =Scenarios!A5 -> Stress | C40: =IF(A40=0,0,VLOOKUP(A40,Base_Value!$B$1:$C$27,2,0)*Assumptions!$C$24*Scenarios!$C$5) -> 1487545.2 | D40: =IF(A40=0,0,Assumptions!$C$26*Assumptions!$C$27) -> 15000 | E40: 0 | F40: =IF(OR(A40=0,A40=1),0,(VLOOKUP($A$34,Base_Value!$B$1:$C$27,2,0)-VLOOKUP($A$46,Base_Value!$B$1:$C$27,2,0))/12) -> 2090000 | H40: =SUM(C40:G40) -> 3592545.2
A41: 7 | B41: =Scenarios!A5 -> Stress | C41: =IF(A41=0,0,VLOOKUP(A41,Base_Value!$B$1:$C$27,2,0)*Assumptions!$C$24*Scenarios!$C$5) -> 1487545.2 | D41: =IF(A41=0,0,Assumptions!$C$26*Assumptions!$C$27) -> 15000 | E41: 0 | F41: =IF(OR(A41=0,A41=1),0,(VLOOKUP($A$34,Base_Value!$B$1:$C$27,2,0)-VLOOKUP($A$46,Base_Value!$B$1:$C$27,2,0))/12) -> 2090000 | H41: =SUM(C41:G41) -> 3592545.2
A42: 8 | B42: =Scenarios!A5 -> Stress | C42: =IF(A42=0,0,VLOOKUP(A42,Base_Value!$B$1:$C$27,2,0)*Assumptions!$C$24*Scenarios!$C$5) -> 1487545.2 | D42: =IF(A42=0,0,Assumptions!$C$26*Assumptions!$C$27) -> 15000 | E42: 0 | F42: =IF(OR(A42=0,A42=1),0,(VLOOKUP($A$34,Base_Value!$B$1:$C$27,2,0)-VLOOKUP($A$46,Base_Value!$B$1:$C$27,2,0))/12) -> 2090000 | H42: =SUM(C42:G42) -> 3592545.2
A43: 9 | B43: =Scenarios!A5 -> Stress | C43: =IF(A43=0,0,VLOOKUP(A43,Base_Value!$B$1:$C$27,2,0)*Assumptions!$C$24*Scenarios!$C$5) -> 1487545.2 | D43: =IF(A43=0,0,Assumptions!$C$26*Assumptions!$C$27) -> 15000 | E43: 0 | F43: =IF(OR(A43=0,A43=1),0,(VLOOKUP($A$34,Base_Value!$B$1:$C$27,2,0)-VLOOKUP($A$46,Base_Value!$B$1:$C$27,2,0))/12) -> 2090000 | H43: =SUM(C43:G43) -> 3592545.2
...

Sheet WACC
A1: WACC Calculation
A2: Metric | B2: Values (Pct)
A3: Cost of Equity | B3: =Assumptions!C29 -> 0.128
A4: Cost of Debt | B4: =Assumptions!C30 -> 0.065
A5: Debt Ratio | B5: =Assumptions!C31 -> 0.7
A6: Equity Ratio | B6: =100%-B5 -> 0.3
A7: Tax Rate | B7: =Assumptions!C33 -> 0.25
A8: WACC | B8: =B6*B3+B5*B4*(1-B7) -> 0.072525

Sheet DCF
A1: Discounted Cash Flow
A2: Scenario | B2: NPV(Net Present Value) | C2: IRR(Internal Rate Of Return)
A3: Base | B3: =NPV(Assumptions!$C$34,Cashflow!$C$5:$C$16)+NPV(Assumptions!$C$34,Cashflow!$F$5:$F$16)+Cashflow!$E$16/(1+Assumptions!$C$34)^12-Assumptions!$C$7 -> 7841.2191 | C3: =IRR(Cashflow!$H$4:$H$16) -> 0.072971752
A4: Downside | B4: =NPV(Assumptions!$C$34,Cashflow!C6:$C$16)+NPV(Assumptions!$C$34,Cashflow!$F$19:$F$31)+Cashflow!$E$16/(1+Assumptions!$C$34)^12-Assumptions!$C$7 -> -4052266.4 | C4: =IRR(Cashflow!$H$19:$H$31) -> 0.043865955
A5: Stress | B5: =NPV(Assumptions!$C$34,Cashflow!C7:$C$16)+NPV(Assumptions!$C$34,Cashflow!$F$34:$F$46)+Cashflow!$E$16/(1+Assumptions!$C$34)^12-Assumptions!$C$7 -> -6651911.1 | C5: =IRR(Cashflow!$H$34:$H$46) -> 0.027947066

Sheet Summary
A1: Summary Table
A2: Key Output | B2: Base
A3: BV at Delivery | B3: =Base_Value!$H$2 -> 45600000
A4: MV at Delivery | B4: =Market_Value!$E$3 -> 45600000
A5: Year-1 Rent | B5: ='LRF-Model'!$E$3 -> 4722365.8
A6: Residual @ Lease End | B6: =Cashflow!$E$16 -> 19904400
A7: Project NPV | B7: =DCF!$B$3 -> 7841.2191
A8: Project IRR | B8: =DCF!$C$3 -> 0.072971752
A9: WACC | B9: =WACC!$B$8 -> 0.072525
A12: Note:-
A13: Condition | B13: Interpretation
A14: IRR > WACC | B14: Value is created; the investment earns returns above the required cost of capital
A15: IRR = WACC | B15: Break-even / fairly priced; no economic value is created or destroyed
A16: IRR < WACC | B16: Value is destroyed; returns are insufficient to compensate capital providers

Sheet Graphs
A2: Dashboard >>>

Sheet Helping Table
B2: BV | H2: MV(Market Value) | N2: Residual
B3: Year | C3: Base | D3: Downside | E3: Stress | H3: Year | I3: Base | J3: Downside | K3: Stress | N3: Year | O3: Base | P3: Downside | Q3: Stress
B4: 0 | C4: =MAX(Base_Value!$H$2*EXP(-Base_Value!$H$3*'Helping Table'!$B4),45%*Base_Value!$H$2) -> 45600000 | D4: =C4 -> 45600000 | E4: =C4 -> 45600000 | H4: 0 | I4: =C4*Scenarios!$B$3 -> 45600000 | J4: =D4*Scenarios!$B$4 -> 36480000 | K4: =E4*Scenarios!$B$5 -> 27360000 | N4: 0 | O4: =I4*(1-Assumptions!$C$28) -> 44232000 | P4: =J4*(1-Assumptions!$C$28) -> 35385600 | Q4: =K4*(1-Assumptions!$C$28) -> 26539200
B5: 1 | C5: =MAX(Base_Value!$H$2*EXP(-Base_Value!$H$3*'Helping Table'!$B5),45%*Base_Value!$H$2) -> 38760000 | D5: =C5 -> 38760000 | E5: =C5 -> 38760000 | H5: 1 | I5: =C5*Scenarios!$B$3 -> 38760000 | J5: =D5*Scenarios!$B$4 -> 31008000 | K5: =E5*Scenarios!$B$5 -> 23256000 | N5: 1 | O5: =I5*(1-Assumptions!$C$28) -> 37597200 | P5: =J5*(1-Assumptions!$C$28) -> 30077760 | Q5: =K5*(1-Assumptions!$C$28) -> 22558320
B6: 2 | C6: =MAX(Base_Value!$H$2*EXP(-Base_Value!$H$3*'Helping Table'!$B6),45%*Base_Value!$H$2) -> 32946000 | D6: =C6 -> 32946000 | E6: =C6 -> 32946000 | H6: 2 | I6: =C6*Scenarios!$B$3 -> 32946000 | J6: =D6*Scenarios!$B$4 -> 26356800 | K6: =E6*Scenarios!$B$5 -> 19767600 | N6: 2 | O6: =I6*(1-Assumptions!$C$28) -> 31957620 | P6: =J6*(1-Assumptions!$C$28) -> 25566096 | Q6: =K6*(1-Assumptions!$C$28) -> 19174572
B7: 3 | C7: =MAX(Base_Value!$H$2*EXP(-Base_Value!$H$3*'Helping Table'!$B7),45%*Base_Value!$H$2) -> 28004100 | D7: =C7 -> 28004100 | E7: =C7 -> 28004100 | H7: 3 | I7: =C7*Scenarios!$B$3 -> 28004100 | J7: =D7*Scenarios!$B$4 -> 22403280 | K7: =E7*Scenarios!$B$5 -> 16802460 | N7: 3 | O7: =I7*(1-Assumptions!$C$28) -> 27163977 | P7: =J7*(1-Assumptions!$C$28) -> 21731182 | Q7: =K7*(1-Assumptions!$C$28) -> 16298386
B8: 4 | C8: =MAX(Base_Value!$H$2*EXP(-Base_Value!$H$3*'Helping Table'!$B8),45%*Base_Value!$H$2) -> 23803485 | D8: =C8 -> 23803485 | E8: =C8 -> 23803485 | H8: 4 | I8: =C8*Scenarios!$B$3 -> 23803485 | J8: =D8*Scenarios!$B$4 -> 19042788 | K8: =E8*Scenarios!$B$5 -> 14282091 | N8: 4 | O8: =I8*(1-Assumptions!$C$28) -> 23089380 | P8: =J8*(1-Assumptions!$C$28) -> 18471504 | Q8: =K8*(1-Assumptions!$C$28) -> 13853628
B9: 5 | C9: =MAX(Base_Value!$H$2*EXP(-Base_Value!$H$3*'Helping Table'!$B9),45%*Base_Value!$H$2) -> 20520000 | D9: =C9 -> 20520000 | E9: =C9 -> 20520000 | H9: 5 | I9: =C9*Scenarios!$B$3 -> 20520000 | J9: =D9*Scenarios!$B$4 -> 16416000 | K9: =E9*Scenarios!$B$5 -> 12312000 | N9: 5 | O9: =I9*(1-Assumptions!$C$28) -> 19904400 | P9: =J9*(1-Assumptions!$C$28) -> 15923520 | Q9: =K9*(1-Assumptions!$C$28) -> 11942640
B10: 6 | C10: =MAX(Base_Value!$H$2*EXP(-Base_Value!$H$3*'Helping Table'!$B10),45%*Base_Value!$H$2) -> 20520000 | D10: =C10 -> 20520000 | E10: =C10 -> 20520000 | H10: 6 | I10: =C10*Scenarios!$B$3 -> 20520000 | J10: =D10*Scenarios!$B$4 -> 16416000 | K10: =E10*Scenarios!$B$5 -> 12312000 | N10: 6 | O10: =I10*(1-Assumptions!$C$28) -> 19904400 | P10: =J10*(1-Assumptions!$C$28) -> 15923520 | Q10: =K10*(1-Assumptions!$C$28) -> 11942640
B11: 7 | C11: =MAX(Base_Value!$H$2*EXP(-Base_Value!$H$3*'Helping Table'!$B11),45%*Base_Value!$H$2) -> 20520000 | D11: =C11 -> 20520000 | E11: =C11 -> 20520000 | H11: 7 | I11: =C11*Scenarios!$B$3 -> 20520000 | J11: =D11*Scenarios!$B$4 -> 16416000 | K11: =E11*Scenarios!$B$5 -> 12312000 | N11: 7 | O11: =I11*(1-Assumptions!$C$28) -> 19904400 | P11: =J11*(1-Assumptions!$C$28) -> 15923520 | Q11: =K11*(1-Assumptions!$C$28) -> 11942640
B12: 8 | C12: =MAX(Base_Value!$H$2*EXP(-Base_Value!$H$3*'Helping Table'!$B12),45%*Base_Value!$H$2) -> 20520000 | D12: =C12 -> 20520000 | E12: =C12 -> 20520000 | H12: 8 | I12: =C12*Scenarios!$B$3 -> 20520000 | J12: =D12*Scenarios!$B$4 -> 16416000 | K12: =E12*Scenarios!$B$5 -> 12312000 | N12: 8 | O12: =I12*(1-Assumptions!$C$28) -> 19904400 | P12: =J12*(1-Assumptions!$C$28) -> 15923520 | Q12: =K12*(1-Assumptions!$C$28) -> 11942640
B13: 9 | C13: =MAX(Base_Value!$H$2*EXP(-Base_Value!$H$3*'Helping Table'!$B13),45%*Base_Value!$H$2) -> 20520000 | D13: =C13 -> 20520000 | E13: =C13 -> 20520000 | H13: 9 | I13: =C13*Scenarios!$B$3 -> 20520000 | J13: =D13*Scenarios!$B$4 -> 16416000 | K13: =E13*Scenarios!$B$5 -> 12312000 | N13: 9 | O13: =I13*(1-Assumptions!$C$28) -> 19904400 | P13: =J13*(1-Assumptions!$C$28) -> 15923520 | Q13: =K13*(1-Assumptions!$C$28) -> 11942640
B14: 10 | C14: =MAX(Base_Value!$H$2*EXP(-Base_Value!$H$3*'Helping Table'!$B14),45%*Base_Value!$H$2) -> 20520000 | D14: =C14 -> 20520000 | E14: =C14 -> 20520000 | H14: 10 | I14: =C14*Scenarios!$B$3 -> 20520000 | J14: =D14*Scenarios!$B$4 -> 16416000 | K14: =E14*Scenarios!$B$5 -> 12312000 | N14: 10 | O14: =I14*(1-Assumptions!$C$28) -> 19904400 | P14: =J14*(1-Assumptions!$C$28) -> 15923520 | Q14: =K14*(1-Assumptions!$C$28) -> 11942640
B15: 11 | C15: =MAX(Base_Value!$H$2*EXP(-Base_Value!$H$3*'Helping Table'!$B15),45%*Base_Value!$H$2) -> 20520000 | D15: =C15 -> 20520000 | E15: =C15 -> 20520000 | H15: 11 | I15: =C15*Scenarios!$B$3 -> 20520000 | J15: =D15*Scenarios!$B$4 -> 16416000 | K15: =E15*Scenarios!$B$5 -> 12312000 | N15: 11 | O15: =I15*(1-Assumptions!$C$28) -> 19904400 | P15: =J15*(1-Assumptions!$C$28) -> 15923520 | Q15: =K15*(1-Assumptions!$C$28) -> 11942640
... B29: 25 | C29: =MAX(Base_Value!$H$2*EXP(-Base_Value!$H$3*'Helping Table'!$B29),45%*Base_Value!$H$2) -> 20520000 | D29: =C29 -> 20520000 | E29: =C29 -> 20520000 | H29: 25 | I29: =C29*Scenarios!$B$3 -> 20520000 | J29: =D29*Scenarios!$B$4 -> 16416000 | K29: =E29*Scenarios!$B$5 -> 12312000 | N29: 25 | O29: =I29*(1-Assumptions!$C$28) -> 19904400 | P29: =J29*(1-Assumptions!$C$28) -> 15923520 | Q29: =K29*(1-Assumptions!$C$28) -> 11942640

Sheet Valuation Summary
A1: Aircraft Valuation Model – Detailed Executive Summary
A3: 1. Overview of the Valuation Framework
A4: This aircraft valuation model has been developed using a discounted cash flow (DCF) framework consistent with industry practice in aircraft leasing, structured finance, and investment committee (IC) review. The objective of the model is to assess whether the assumed lease rental profile and residual value assumptions generate a return that meets the required cost of capital. The valuation is performed on a single-aircraft basis and reflects a long-term ownership perspective. The model explicitly forecasts contractual lease rental cash flows over the lease tenor and incorporates a terminal residual value at lease expiry, both of which are discounted using the assumed weighted average cost of capital (WACC).
A6: 2. Aircraft, Pricing, and Transaction Assumptions
A7: The aircraft acquisition value used in the model is derived from the manufacturer list price and adjusted to reflect prevailing market conditions. These adjustments include a market discount to account for negotiated transaction pricing and a model factor to reflect the aircraft’s technical configuration, market liquidity, and relative demand within its segment. The resulting base value is intended to represent a realistic purchase price rather than a theoretical or headline figure. The valuation assumes acquisition at this base value at time zero.
A9: 3. Lease Revenue and Maintenance Reserve Assumptions
A10: Lease revenue is modeled as a fixed annual rental amount over the lease term. The annual rent is expressed and analysed through the lease rate factor (LRF), defined as annual rent as a percentage of aircraft value. Maintenance reserves are excluded from economic value creation in the model and are assumed to be broadly cash-neutral over the life of the asset. This treatment reflects standard lessor practice, whereby maintenance reserves are collected to fund future maintenance events and do not represent incremental return to equity.
A12: 4. Discount Rate and Financial Assumptions
A13: All cash flows are discounted using a single WACC, which represents the target return required by investors for the risk profile of the asset. The WACC is applied consistently to lease rental cash flows and the terminal residual value. Discounting is performed on an annual basis using end-of-period conventions. The WACC is treated as an exogenous input and is independently tested through sensitivity analysis to assess exposure to capital market conditions.
A15: 5. Depreciation Methodology and Residual Value Logic
A16: The model applies an economic depreciation framework rather than accounting depreciation. Aircraft value decay is driven by age, utilization, technological obsolescence, and market dynamics. Residual value at lease expiry is estimated based on expected market value at the end of the lease term. A selling cost assumption is applied to derive a net realizable residual value, which is then discounted back to present value using the WACC. This approach ensures that exit value assumptions are conservative, transparent, and aligned with observed secondary market behavior.
A18: 6. Valuation Methodology
... A28: The aircraft valuation model is internally consistent, transparent, and aligned with industry best practice. The assumptions, depreciation logic, and sensitivity results provide a clear view of both base-case economics and downside risk exposure. The model is suitable for use in investment committee review, credit assessment, and client-facing valuation support.
